Workbook

Sheet Comece Aqui

Sheet Meu Mês
D3: Jan | E3: Fev | F3: Mar | G3: Abr | H3: Mai | I3: Jun | J3: Jul | K3: Ago | L3: Set | M3: Out | N3: Nov | O3: Dez | P3: Total Ano | Q3: Média
B5: ENTRADAS
B6: Salário | C6: Pró-labore, CLT, principal | D6: 0 | E6: 0 | F6: 0 | G6: 0 | H6: 0 | I6: 0 | J6: 0 | K6: 0 | L6: 0 | M6: 0 | N6: 0 | O6: 0 | P6: =SUM(D6:O6) -> 0 | Q6: =IFERROR(AVERAGEIF(D6:O6,">0"),0) -> 0
B7: Renda extra | C7: Freelas, comissões, bônus | D7: 0 | E7: 0 | F7: 0 | G7: 0 | H7: 0 | I7: 0 | J7: 0 | K7: 0 | L7: 0 | M7: 0 | N7: 0 | O7: 0 | P7: =SUM(D7:O7) -> 0 | Q7: =IFERROR(AVERAGEIF(D7:O7,">0"),0) -> 0
B8: Aluguéis | C8: Receita de imóveis | D8: 0 | E8: 0 | F8: 0 | G8: 0 | H8: 0 | I8: 0 | J8: 0 | K8: 0 | L8: 0 | M8: 0 | N8: 0 | O8: 0 | P8: =SUM(D8:O8) -> 0 | Q8: =IFERROR(AVERAGEIF(D8:O8,">0"),0) -> 0
B9: Outras | C9: Dividendos, vendas, etc. | D9: 0 | E9: 0 | F9: 0 | G9: 0 | H9: 0 | I9: 0 | J9: 0 | K9: 0 | L9: 0 | M9: 0 | N9: 0 | O9: 0 | P9: =SUM(D9:O9) -> 0 | Q9: =IFERROR(AVERAGEIF(D9:O9,">0"),0) -> 0
B10: Subtotal | D10: =SUM(D6:D9) -> 0 | E10: =SUM(E6:E9) -> 0 | F10: =SUM(F6:F9) -> 0 | G10: =SUM(G6:G9) -> 0 | H10: =SUM(H6:H9) -> 0 | I10: =SUM(I6:I9) -> 0 | J10: =SUM(J6:J9) -> 0 | K10: =SUM(K6:K9) -> 0 | ... P10: =SUM(P6:P9) -> 0 | Q10: =IFERROR(AVERAGE(D10:O10),0) -> 0
B12: MORADIA
B13: Moradia | C13: Aluguel ou financiamento | D13: 0 | E13: 0 | F13: 0 | G13: 0 | H13: 0 | I13: 0 | J13: 0 | K13: 0 | L13: 0 | M13: 0 | N13: 0 | O13: 0 | P13: =SUM(D13:O13) -> 0 | Q13: =IFERROR(AVERAGEIF(D13:O13,">0"),0) -> 0
B14: Moradia | C14: Condomínio | D14: 0 | E14: 0 | F14: 0 | G14: 0 | H14: 0 | I14: 0 | J14: 0 | K14: 0 | L14: 0 | M14: 0 | N14: 0 | O14: 0 | P14: =SUM(D14:O14) -> 0 | Q14: =IFERROR(AVERAGEIF(D14:O14,">0"),0) -> 0
B15: Moradia | C15: Contas (luz, água, gás, internet) | D15: 0 | E15: 0 | F15: 0 | G15: 0 | H15: 0 | I15: 0 | J15: 0 | K15: 0 | L15: 0 | M15: 0 | N15: 0 | O15: 0 | P15: =SUM(D15:O15) -> 0 | Q15: =IFERROR(AVERAGEIF(D15:O15,">0"),0) -> 0
B16: Moradia | C16: Outros | D16: 0 | E16: 0 | F16: 0 | G16: 0 | H16: 0 | I16: 0 | J16: 0 | K16: 0 | L16: 0 | M16: 0 | N16: 0 | O16: 0 | P16: =SUM(D16:O16) -> 0 | Q16: =IFERROR(AVERAGEIF(D16:O16,">0"),0) -> 0
B17: Subtotal | D17: =SUM(D13:D16) -> 0 | E17: =SUM(E13:E16) -> 0 | F17: =SUM(F13:F16) -> 0 | G17: =SUM(G13:G16) -> 0 | H17: =SUM(H13:H16) -> 0 | I17: =SUM(I13:I16) -> 0 | J17: =SUM(J13:J16) -> 0 | K17: =SUM(K13:K16) -> 0 | ... P17: =SUM(P13:P16) -> 0 | Q17: =IFERROR(AVERAGE(D17:O17),0) -> 0
B19: ALIMENTAÇÃO
B20: Alimentação | C20: Mercado e feira | D20: 0 | E20: 0 | F20: 0 | G20: 0 | H20: 0 | I20: 0 | J20: 0 | K20: 0 | L20: 0 | M20: 0 | N20: 0 | O20: 0 | P20: =SUM(D20:O20) -> 0 | Q20: =IFERROR(AVERAGEIF(D20:O20,">0"),0) -> 0
B21: Alimentação | C21: Restaurantes e delivery | D21: 0 | E21: 0 | F21: 0 | G21: 0 | H21: 0 | I21: 0 | J21: 0 | K21: 0 | L21: 0 | M21: 0 | N21: 0 | O21: 0 | P21: =SUM(D21:O21) -> 0 | Q21: =IFERROR(AVERAGEIF(D21:O21,">0"),0) -> 0
B22: Alimentação | C22: Outros | D22: 0 | E22: 0 | F22: 0 | G22: 0 | H22: 0 | I22: 0 | J22: 0 | K22: 0 | L22: 0 | M22: 0 | N22: 0 | O22: 0 | P22: =SUM(D22:O22) -> 0 | Q22: =IFERROR(AVERAGEIF(D22:O22,">0"),0) -> 0
B23: Subtotal | D23: =SUM(D20:D22) -> 0 | E23: =SUM(E20:E22) -> 0 | F23: =SUM(F20:F22) -> 0 | G23: =SUM(G20:G22) -> 0 | H23: =SUM(H20:H22) -> 0 | I23: =SUM(I20:I22) -> 0 | J23: =SUM(J20:J22) -> 0 | K23: =SUM(K20:K22) -> 0 | ... P23: =SUM(P20:P22) -> 0 | Q23: =IFERROR(AVERAGE(D23:O23),0) -> 0
B25: TRANSPORTE
B26: Transporte | C26: Combustível | D26: 0 | E26: 0 | F26: 0 | G26: 0 | H26: 0 | I26: 0 | J26: 0 | K26: 0 | L26: 0 | M26: 0 | N26: 0 | O26: 0 | P26: =SUM(D26:O26) -> 0 | Q26: =IFERROR(AVERAGEIF(D26:O26,">0"),0) -> 0
B27: Transporte | C27: Aplicativos e estacionamento | D27: 0 | E27: 0 | F27: 0 | G27: 0 | H27: 0 | I27: 0 | J27: 0 | K27: 0 | L27: 0 | M27: 0 | N27: 0 | O27: 0 | P27: =SUM(D27:O27) -> 0 | Q27: =IFERROR(AVERAGEIF(D27:O27,">0"),0) -> 0
B28: Transporte | C28: Manutenção e seguro | D28: 0 | E28: 0 | F28: 0 | G28: 0 | H28: 0 | I28: 0 | J28: 0 | K28: 0 | L28: 0 | M28: 0 | N28: 0 | O28: 0 | P28: =SUM(D28:O28) -> 0 | Q28: =IFERROR(AVERAGEIF(D28:O28,">0"),0) -> 0
B29: Transporte | C29: Outros | D29: 0 | E29: 0 | F29: 0 | G29: 0 | H29: 0 | I29: 0 | J29: 0 | K29: 0 | L29: 0 | M29: 0 | N29: 0 | O29: 0 | P29: =SUM(D29:O29) -> 0 | Q29: =IFERROR(AVERAGEIF(D29:O29,">0"),0) -> 0
B30: Subtotal | D30: =SUM(D26:D29) -> 0 | E30: =SUM(E26:E29) -> 0 | F30: =SUM(F26:F29) -> 0 | G30: =SUM(G26:G29) -> 0 | H30: =SUM(H26:H29) -> 0 | I30: =SUM(I26:I29) -> 0 | J30: =SUM(J26:J29) -> 0 | K30: =SUM(K26:K29) -> 0 | ... P30: =SUM(P26:P29) -> 0 | Q30: =IFERROR(AVERAGE(D30:O30),0) -> 0
B32: SAÚDE E BEM-ESTAR
B33: Saúde | C33: Plano de saúde | D33: 0 | E33: 0 | F33: 0 | G33: 0 | H33: 0 | I33: 0 | J33: 0 | K33: 0 | L33: 0 | M33: 0 | N33: 0 | O33: 0 | P33: =SUM(D33:O33) -> 0 | Q33: =IFERROR(AVERAGEIF(D33:O33,">0"),0) -> 0
B34: Saúde | C34: Farmácia e exames | D34: 0 | E34: 0 | F34: 0 | G34: 0 | H34: 0 | I34: 0 | J34: 0 | K34: 0 | L34: 0 | M34: 0 | N34: 0 | O34: 0 | P34: =SUM(D34:O34) -> 0 | Q34: =IFERROR(AVERAGEIF(D34:O34,">0"),0) -> 0
B35: Saúde | C35: Academia, terapia, bem-estar | D35: 0 | E35: 0 | F35: 0 | G35: 0 | H35: 0 | I35: 0 | J35: 0 | K35: 0 | L35: 0 | M35: 0 | N35: 0 | O35: 0 | P35: =SUM(D35:O35) -> 0 | Q35: =IFERROR(AVERAGEIF(D35:O35,">0"),0) -> 0
B36: Subtotal | D36: =SUM(D33:D35) -> 0 | E36: =SUM(E33:E35) -> 0 | F36: =SUM(F33:F35) -> 0 | G36: =SUM(G33:G35) -> 0 | H36: =SUM(H33:H35) -> 0 | I36: =SUM(I33:I35) -> 0 | J36: =SUM(J33:J35) -> 0 | K36: =SUM(K33:K35) -> 0 | ... P36: =SUM(P33:P35) -> 0 | Q36: =IFERROR(AVERAGE(D36:O36),0) -> 0
B38: EDUCAÇÃO
B39: Educação | C39: Escola, faculdade, MBA | D39: 0 | E39: 0 | F39: 0 | G39: 0 | H39: 0 | I39: 0 | J39: 0 | K39: 0 | L39: 0 | M39: 0 | N39: 0 | O39: 0 | P39: =SUM(D39:O39) -> 0 | Q39: =IFERROR(AVERAGEIF(D39:O39,">0"),0) -> 0
B40: Educação | C40: Cursos e livros | D40: 0 | E40: 0 | F40: 0 | G40: 0 | H40: 0 | I40: 0 | J40: 0 | K40: 0 | L40: 0 | M40: 0 | N40: 0 | O40: 0 | P40: =SUM(D40:O40) -> 0 | Q40: =IFERROR(AVERAGEIF(D40:O40,">0"),0) -> 0
B41: Subtotal | D41: =SUM(D39:D40) -> 0 | E41: =SUM(E39:E40) -> 0 | F41: =SUM(F39:F40) -> 0 | G41: =SUM(G39:G40) -> 0 | H41: =SUM(H39:H40) -> 0 | I41: =SUM(I39:I40) -> 0 | J41: =SUM(J39:J40) -> 0 | K41: =SUM(K39:K40) -> 0 | ... P41: =SUM(P39:P40) -> 0 | Q41: =IFERROR(AVERAGE(D41:O41),0) -> 0
B43: LAZER E PESSOAL
B44: Lazer | C44: Streaming e assinaturas | D44: 0 | E44: 0 | F44: 0 | G44: 0 | H44: 0 | I44: 0 | J44: 0 | K44: 0 | L44: 0 | M44: 0 | N44: 0 | O44: 0 | P44: =SUM(D44:O44) -> 0 | Q44: =IFERROR(AVERAGEIF(D44:O44,">0"),0) -> 0
B45: Lazer | C45: Viagens | D45: 0 | E45: 0 | F45: 0 | G45: 0 | H45: 0 | I45: 0 | J45: 0 | K45: 0 | L45: 0 | M45: 0 | N45: 0 | O45: 0 | P45: =SUM(D45:O45) -> 0 | Q45: =IFERROR(AVERAGEIF(D45:O45,">0"),0) -> 0
B46: Lazer | C46: Compras pessoais | D46: 0 | E46: 0 | F46: 0 | G46: 0 | H46: 0 | I46: 0 | J46: 0 | K46: 0 | L46: 0 | M46: 0 | N46: 0 | O46: 0 | P46: =SUM(D46:O46) -> 0 | Q46: =IFERROR(AVERAGEIF(D46:O46,">0"),0) -> 0
B47: Lazer | C47: Outros | D47: 0 | E47: 0 | F47: 0 | G47: 0 | H47: 0 | I47: 0 | J47: 0 | K47: 0 | L47: 0 | M47: 0 | N47: 0 | O47: 0 | P47: =SUM(D47:O47) -> 0 | Q47: =IFERROR(AVERAGEIF(D47:O47,">0"),0) -> 0
B48: Subtotal | D48: =SUM(D44:D47) -> 0 | E48: =SUM(E44:E47) -> 0 | F48: =SUM(F44:F47) -> 0 | G48: =SUM(G44:G47) -> 0 | H48: =SUM(H44:H47) -> 0 | I48: =SUM(I44:I47) -> 0 | J48: =SUM(J44:J47) -> 0 | K48: =SUM(K44:K47) -> 0 | ... P48: =SUM(P44:P47) -> 0 | Q48: =IFERROR(AVERAGE(D48:O48),0) -> 0
B50: OUTROS
...

Sheet Meu Painel
B3: ENTRADAS | D3: SAÍDAS | F3: INVESTIDO | H3: SOBROU
B4: =SUM('Meu Mês'!D10:O10) -> 0 | D4: =SUM('Meu Mês'!D57:O57) -> 0 | F4: =SUM('Meu Mês'!D63:O63) -> 0 | H4: =SUM('Meu Mês'!D67:O67) -> 0
B8: Distribuição das despesas (ano) | F8: Evolução mensal
B10: Categoria | C10: Total | D10: % | F10: Mês | G10: Entradas | H10: Saídas
B11: Moradia | C11: =SUM('Meu Mês'!D17:O17) -> 0 | D11: =IFERROR(C11/SUM($C$11:$C$17),0) -> 0 | F11: Jan | G11: ='Meu Mês'!D10 -> 0 | H11: ='Meu Mês'!D57 -> 0
B12: Alimentação | C12: =SUM('Meu Mês'!D23:O23) -> 0 | D12: =IFERROR(C12/SUM($C$11:$C$17),0) -> 0 | F12: Fev | G12: ='Meu Mês'!E10 -> 0 | H12: ='Meu Mês'!E57 -> 0
B13: Transporte | C13: =SUM('Meu Mês'!D30:O30) -> 0 | D13: =IFERROR(C13/SUM($C$11:$C$17),0) -> 0 | F13: Mar | G13: ='Meu Mês'!F10 -> 0 | H13: ='Meu Mês'!F57 -> 0
B14: Saúde e Bem-estar | C14: =SUM('Meu Mês'!D36:O36) -> 0 | D14: =IFERROR(C14/SUM($C$11:$C$17),0) -> 0 | F14: Abr | G14: ='Meu Mês'!G10 -> 0 | H14: ='Meu Mês'!G57 -> 0
B15: Educação | C15: =SUM('Meu Mês'!D41:O41) -> 0 | D15: =IFERROR(C15/SUM($C$11:$C$17),0) -> 0 | F15: Mai | G15: ='Meu Mês'!H10 -> 0 | H15: ='Meu Mês'!H57 -> 0
B16: Lazer e Pessoal | C16: =SUM('Meu Mês'!D48:O48) -> 0 | D16: =IFERROR(C16/SUM($C$11:$C$17),0) -> 0 | F16: Jun | G16: ='Meu Mês'!I10 -> 0 | H16: ='Meu Mês'!I57 -> 0
B17: Outros | C17: =SUM('Meu Mês'!D54:O54) -> 0 | D17: =IFERROR(C17/SUM($C$11:$C$17),0) -> 0 | F17: Jul | G17: ='Meu Mês'!J10 -> 0 | H17: ='Meu Mês'!J57 -> 0
F18: Ago | G18: ='Meu Mês'!K10 -> 0 | H18: ='Meu Mês'!K57 -> 0
F19: Set | G19: ='Meu Mês'!L10 -> 0 | H19: ='Meu Mês'!L57 -> 0
F20: Out | G20: ='Meu Mês'!M10 -> 0 | H20: ='Meu Mês'!M57 -> 0
F21: Nov | G21: ='Meu Mês'!N10 -> 0 | H21: ='Meu Mês'!N57 -> 0
F22: Dez | G22: ='Meu Mês'!O10 -> 0 | H22: ='Meu Mês'!O57 -> 0
B40: O que sobrou no seu bolso
B41: Análise do que entrou, saiu e como você usou a sobra ao longo do ano
B43: Sobra do ano | D43: Taxa de poupança | F43: % investido da sobra | H43: Sobra média / mês
B44: =H4 -> 0 | D44: =IFERROR(H4/B4,0) -> 0 | F44: =IFERROR(F4/H4,0) -> 0 | H44: =H4/12 -> 0
B45: Quanto sobrou após as despesas | D45: Sobra ÷ Entradas | F45: O quanto da sobra virou investimento | H45: Média mensal disponível
B47: Diagnóstico
B48: Saúde financeira: | C48: =IF(B44<0,"⚠ Atenção: você gastou mais do que ganhou no ano",IF(D44>=0.2,"✓ Excelente — você está poupando mais de 20% do que ganha",IF(D44>=0.1,"○ Boa — taxa de poupança saudável, dá pra otimizar",IF(D44>0,"△ Apertada — sobrou pouco, vale revisar despesas","⚠ Você não conseguiu poupar nada esse ano")))) -> ⚠ Você não conseguiu poupar nada esse ano
B49: Aproveitamento da sobra: | C49: =IF(H4<=0,"—",IF(F44>=0.7,"✓ Você está fazendo o dinheiro trabalhar — ótima alocação em investimentos",IF(F44>=0.4,"○ Boa parte da sobra virou investimento, mas dá pra mais",IF(F44>0,"△ Pouco da sobra está sendo investido — o resto pode estar parado","⚠ Nada da sua sobra foi investido esse ano")))) -> —
B50: Melhor mês (mais sobra): | C50: {=INDEX(F11:F22,MATCH(MAX(G11:G22-H11:H22),G11:G22-H11:H22,0))&" · "&TEXT(MAX(G11:G22-H11:H22),"R$ #,##0")} -> Jan · R$ 0
B51: Pior mês (menos sobra): | C51: {=INDEX(F11:F22,MATCH(MIN(G11:G22-H11:H22),G11:G22-H11:H22,0))&" · "&TEXT(MIN(G11:G22-H11:H22),"R$ #,##0")} -> Jan · R$ 0
B52: Maior categoria de gasto: | C52: {=INDEX(B11:B17,MATCH(MAX(C11:C17),C11:C17,0))&" · "&TEXT(MAX(C11:C17),"R$ #,##0")&" ("&TEXT(MAX(D11:D17),"0.0%")&")"} -> Moradia · R$ 0 (0.0%)
B57: CAIS INVESTIMENTOS · O norte dos seus Investimentos
